Workbook

Sheet Read me
A1: AI Guardrails — delivery model
A2: Milestones, dependencies and gates are transcribed from solution-docs. The effort model laid over them is an assumption, not an estimate.
A4: How to use it
A5: 1. Open Assumptions. | B5: The only sheet with typed-in numbers, and every one is a placeholder chosen to make the model run. Replace them.
A6: 2. Check the AI-assistance factors. | B6: They assume everyone here delivers with an agentic coding tool. Zero them for the unassisted model.
A7: 3. Set a day rate per role. | B7: Leave them empty and every cost column stays empty rather than showing a misleading zero.
A8: 4. Argue with the sizes and role splits. | B8: Both are judgements, editable on Work items, reasoned in the generator.
A9: 5. Stress it. | B9: Sensitivity moves contingency and assistance together. Pivot data is the flat grain — build your own pivots off it.
A11: How to read a cell
A12: INPUT | B12: An assumption you own. Nothing in the source documentation supplies this value — edit it.
A13: DERIVED | B13: Read from solution-docs at build time. Editing it here changes nothing upstream and is overwritten on the next build.
A14: COMPUTED | B14: A formula over the other two. Never type over it.
A16: What this workbook does not say
A17: No schedule | B17: Milestone order is dependency sequencing. No dates, quarters or durations exist upstream and none are invented here.
A18: Nothing is built | B18: Every work item is planned work. There is no percent-complete column because there is nothing to report against.
A19: The effort model is yours | B19: Not an estimate the programme has produced. That estimation is owed by delivery and product leads and has not been supplied.
A20: Phases 3–5 are not funded | B20: They are estimated because the feature set is defined across all five phases — not because the work may start before the gate.
A21: AI assistance is this workbook's own assumption | B21: Stated in no source document. It reduces effort per role, never elapsed time — the external dependencies are approval-bound.
A23: Where the content comes from
A24: Sheet | B24: Source
A25: Work items | B25: MILESTONES.md §3–§7 completion criteria, document order
A26: Roadmap | B26: MILESTONES.md §2–§7; AGR-020 five-phase delivery
A27: Dependencies | B27: DEPENDENCIES.md §2 register and §3 detail
A28: Release gates | B28: RELEASE-CRITERIA.md gate tables
A29: Roles | B29: TEAM-AND-OWNERSHIP.md §1 four ownership groups
A30: Sizes and role splits | B30: Nowhere — assumed here. See Assumptions.
A31: AI-assistance factors | B31: Nowhere, and in no other document — assumed here.
A32: Every chart and rollup | B32: Formulas over the two rows above.

Sheet Dashboard
A1: Dashboard
A2: Every figure is a formula over Assumptions and Work items. Change an assumption and every chart here moves with it.
A5: TOTAL DAYS, AFTER AI ASSIST | C5: TOTAL DAYS, BEFORE AI ASSIST | E5: DAYS THE ASSIST ASSUMPTION REMOVES | G5: DAYS BEHIND THE PHASE 1–2 GATE
A6: ='Work items'!$Q$66 | C6: ='Work items'!$G$66 | E6: ='Work items'!$G$66-'Work items'!$Q$66 | G6: =SUMIF('Work items'!$B$6:$B$65,"M1",'Work items'!$Q$6:$Q$65) + SUMIF('Work items'!$B$6:$B$65,"M2",'Work items'!$Q$6:$Q$65)
A7: The headline number. It is a model output, not an estimate. | C7: Set every assistance factor to zero and the headline becomes this. | E7: Removed by an assumption this workbook makes on its own authority. | G7: M1 and M2 only. The rest is estimated, and must not be resourced yet.
A9: Where the effort sits
A10: Milestone | B10: Days after AI assist
A11: M1 | B11: =SUMIF('Work items'!$B$6:$B$65,$A$11,'Work items'!$Q$6:$Q$65)
A12: M2 | B12: =SUMIF('Work items'!$B$6:$B$65,$A$12,'Work items'!$Q$6:$Q$65)
A13: M3 | B13: =SUMIF('Work items'!$B$6:$B$65,$A$13,'Work items'!$Q$6:$Q$65)
A14: M4 | B14: =SUMIF('Work items'!$B$6:$B$65,$A$14,'Work items'!$Q$6:$Q$65)
A15: M5 | B15: =SUMIF('Work items'!$B$6:$B$65,$A$15,'Work items'!$Q$6:$Q$65)
A26: What the AI-assistance assumption buys
A27: Role | B27: Before assist | C27: After assist
A28: AIG | B28: =SUMPRODUCT('Work items'!$G$6:$G$65,'Work items'!$H$6:$H$65) | C28: =SUM('Work items'!$M$6:$M$65)
A29: OPS | B29: =SUMPRODUCT('Work items'!$G$6:$G$65,'Work items'!$I$6:$I$65) | C29: =SUM('Work items'!$N$6:$N$65)
A30: SEC | B30: =SUMPRODUCT('Work items'!$G$6:$G$65,'Work items'!$J$6:$J$65) | C30: =SUM('Work items'!$O$6:$O$65)
A31: CONS | B31: =SUMPRODUCT('Work items'!$G$6:$G$65,'Work items'!$K$6:$K$65) | C31: =SUM('Work items'!$P$6:$P$65)
A43: How the role mix shifts across the milestones
A44: Milestone | B44: AIG | C44: OPS | D44: SEC | E44: CONS
A45: M1 | B45: =SUMIF('Work items'!$B$6:$B$65,$A$45,'Work items'!$M$6:$M$65) | C45: =SUMIF('Work items'!$B$6:$B$65,$A$45,'Work items'!$N$6:$N$65) | D45: =SUMIF('Work items'!$B$6:$B$65,$A$45,'Work items'!$O$6:$O$65) | E45: =SUMIF('Work items'!$B$6:$B$65,$A$45,'Work items'!$P$6:$P$65)
A46: M2 | B46: =SUMIF('Work items'!$B$6:$B$65,$A$46,'Work items'!$M$6:$M$65) | C46: =SUMIF('Work items'!$B$6:$B$65,$A$46,'Work items'!$N$6:$N$65) | D46: =SUMIF('Work items'!$B$6:$B$65,$A$46,'Work items'!$O$6:$O$65) | E46: =SUMIF('Work items'!$B$6:$B$65,$A$46,'Work items'!$P$6:$P$65)
A47: M3 | B47: =SUMIF('Work items'!$B$6:$B$65,$A$47,'Work items'!$M$6:$M$65) | C47: =SUMIF('Work items'!$B$6:$B$65,$A$47,'Work items'!$N$6:$N$65) | D47: =SUMIF('Work items'!$B$6:$B$65,$A$47,'Work items'!$O$6:$O$65) | E47: =SUMIF('Work items'!$B$6:$B$65,$A$47,'Work items'!$P$6:$P$65)
A48: M4 | B48: =SUMIF('Work items'!$B$6:$B$65,$A$48,'Work items'!$M$6:$M$65) | C48: =SUMIF('Work items'!$B$6:$B$65,$A$48,'Work items'!$N$6:$N$65) | D48: =SUMIF('Work items'!$B$6:$B$65,$A$48,'Work items'!$O$6:$O$65) | E48: =SUMIF('Work items'!$B$6:$B$65,$A$48,'Work items'!$P$6:$P$65)
A49: M5 | B49: =SUMIF('Work items'!$B$6:$B$65,$A$49,'Work items'!$M$6:$M$65) | C49: =SUMIF('Work items'!$B$6:$B$65,$A$49,'Work items'!$N$6:$N$65) | D49: =SUMIF('Work items'!$B$6:$B$65,$A$49,'Work items'!$O$6:$O$65) | E49: =SUMIF('Work items'!$B$6:$B$65,$A$49,'Work items'!$P$6:$P$65)
A60: The shape of the work
A61: Size | B61: Work items | C61: Days after AI assist
A62: S | B62: =COUNTIF('Work items'!$E$6:$E$65,$A$62) | C62: =SUMIF('Work items'!$E$6:$E$65,$A$62,'Work items'!$Q$6:$Q$65)
A63: M | B63: =COUNTIF('Work items'!$E$6:$E$65,$A$63) | C63: =SUMIF('Work items'!$E$6:$E$65,$A$63,'Work items'!$Q$6:$Q$65)
A64: L | B64: =COUNTIF('Work items'!$E$6:$E$65,$A$64) | C64: =SUMIF('Work items'!$E$6:$E$65,$A$64,'Work items'!$Q$6:$Q$65)
A65: XL | B65: =COUNTIF('Work items'!$E$6:$E$65,$A$65) | C65: =SUMIF('Work items'!$E$6:$E$65,$A$65,'Work items'!$Q$6:$Q$65)
A77: Effort by workstream
A78: Workstream | B78: Work items | C78: Days after AI assist
A79: Contract | B79: =COUNTIF('Work items'!$C$6:$C$65,$A$79) | C79: =SUMIF('Work items'!$C$6:$C$65,$A$79,'Work items'!$Q$6:$Q$65)
A80: Evaluation | B80: =COUNTIF('Work items'!$C$6:$C$65,$A$80) | C80: =SUMIF('Work items'!$C$6:$C$65,$A$80,'Work items'!$Q$6:$Q$65)
A81: Connector | B81: =COUNTIF('Work items'!$C$6:$C$65,$A$81) | C81: =SUMIF('Work items'!$C$6:$C$65,$A$81,'Work items'!$Q$6:$Q$65)
A82: Runtime | B82: =COUNTIF('Work items'!$C$6:$C$65,$A$82) | C82: =SUMIF('Work items'!$C$6:$C$65,$A$82,'Work items'!$Q$6:$Q$65)
A83: Audit | B83: =COUNTIF('Work items'!$C$6:$C$65,$A$83) | C83: =SUMIF('Work items'!$C$6:$C$65,$A$83,'Work items'!$Q$6:$Q$65)
A84: Observability | B84: =COUNTIF('Work items'!$C$6:$C$65,$A$84) | C84: =SUMIF('Work items'!$C$6:$C$65,$A$84,'Work items'!$Q$6:$Q$65)
A85: Infrastructure | B85: =COUNTIF('Work items'!$C$6:$C$65,$A$85) | C85: =SUMIF('Work items'!$C$6:$C$65,$A$85,'Work items'!$Q$6:$Q$65)
...

Sheet Assumptions
A1: Assumptions — the only sheet you edit
A2: Everything else in this workbook is either transcribed from the documentation or computed from what is here.
A4: The person-day values below are PLACEHOLDERS chosen so the model runs. No effort estimate exists upstream. Replace them before quoting any total.
A7: Size | B7: Label | C7: Person-days (unassisted) | D7: What it means
A8: S | B8: Small | C8: 5 | D8: A bounded change inside one component.
A9: M | B9: Medium | C9: 15 | D9: One component, built and tested.
A10: L | B10: Large | C10: 40 | D10: A subsystem, or a contract surface with published semantics.
A11: XL | B11: Extra large | C11: 80 | D11: A subsystem of a kind this platform has not built before.
A14: Role | B14: Name | C14: Day rate | D14: Mandate
A15: AIG | B15: AI Guardrails team | D15: Architecture, policy schemas, evaluation contract, runtime, connectors, integrations, compatibility, telemetry, documentation, deployment artifacts
A16: OPS | B16: Platform operations | D16: The provider's own hosted infrastructure day to day — deployment, monitoring, capacity, networking, incident response
A17: SEC | B17: Security and governance | D17: Organization-level policy requirements; approves policy, risk, retention and audit rules
A18: CONS | B18: Consuming teams | D18: Applications and workloads bound to policies, including any internal gateway they operate themselves
A21: Contingency | B21: Applied to every work item | C21: 0 | D21: One uplift across the whole model. Zero by default — inventing a contingency figure on your behalf would defeat the point of this sheet. Sensitivity shows the range.
A23: Role | B23: AI assist | C23: Effort reduction | D23: Why this figure and not another
A24: AIG | B24: AI Guardrails team | C24: 0.3 | D24: Contracts, policy schemas, evaluator adapters, connectors, runtime, deployment artifacts, tests and documentation — greenfield, well-specified, code-shaped work, and by far the largest share of this model. This is where an agentic coding tool earns most of what it is going to earn.
A25: OPS | B25: Platform operations | C25: 0.15 | D25: Infrastructure modules, dashboards and runbooks compress. Account provisioning, managed-engine access in the target Regions, capacity and incident response are approval-bound and wall-clock, and do not.
A26: SEC | B26: Security and governance | C26: 0.1 | D26: Drafting policy requirements and assembling review evidence compresses. Judgement, approval and accountability do not — and the criteria that would satisfy security sign-off are themselves undefined today.
A27: CONS | B27: Consuming teams | C27: 0.1 | D27: Onboarding and connector installation compress a little. The validation demonstration is gated by a second team's availability and willingness, which no tool shortens.
A29: Planning assumptions, not measurements. Published results range from large gains to none, and one controlled trial found experienced engineers slower. Zero these four cells and the workbook recovers the unassisted model.
A30: Day rates ship empty on purpose: with no rate set, every cost column stays blank rather than computing a zero that could pass for a real figure.

Sheet Work items
A1: Work items
A2: One row per milestone completion criterion, in document order. Size and role split are yours to edit; everything shaded blue is a formula. Filter from the header row.
A5: ID | B5: Milestone | C5: Workstream | D5: Work item | E5: Size | F5: Base days | G5: Days incl. cont. (unassisted) | H5: AIG share | I5: OPS share | J5: SEC share | K5: CONS share | L5: Share Σ | M5: AIG days | N5: OPS days | O5: SEC days | P5: CONS days | Q5: Days after AI assist
A6: WI-001 | B6: M1 | C6: Contract | D6: Evaluation contract defined and published — request structure, decision structure, reason codes, policy-version semantics, expressed independently of any gateway or vendor | E6: L | F6: =VLOOKUP($E6,Assumptions!$A$8:$C$11,3,FALSE) | G6: =$F6*(1+Assumptions!$C$21) | H6: 1 | I6: 0 | J6: 0 | K6: 0 | L6: =SUM(H6:K6) | M6: =$G6*H6*(1-Assumptions!$C$24) | N6: =$G6*I6*(1-Assumptions!$C$25) | O6: =$G6*J6*(1-Assumptions!$C$26) | P6: =$G6*K6*(1-Assumptions!$C$27) | Q6: =SUM(M6:P6)
A7: WI-002 | B7: M1 | C7: Contract | D7: Guardrail policy format defined as a versioned, vendor-independent schema | E7: L | F7: =VLOOKUP($E7,Assumptions!$A$8:$C$11,3,FALSE) | G7: =$F7*(1+Assumptions!$C$21) | H7: 1 | I7: 0 | J7: 0 | K7: 0 | L7: =SUM(H7:K7) | M7: =$G7*H7*(1-Assumptions!$C$24) | N7: =$G7*I7*(1-Assumptions!$C$25) | O7: =$G7*J7*(1-Assumptions!$C$26) | P7: =$G7*K7*(1-Assumptions!$C$27) | Q7: =SUM(M7:P7)
A8: WI-003 | B8: M1 | C8: Evaluation | D8: Amazon Bedrock Guardrails adapter, normalizing vendor responses into the platform's own decision structure before they reach any policy or connector | E8: L | F8: =VLOOKUP($E8,Assumptions!$A$8:$C$11,3,FALSE) | G8: =$F8*(1+Assumptions!$C$21) | H8: 1 | I8: 0 | J8: 0 | K8: 0 | L8: =SUM(H8:K8) | M8: =$G8*H8*(1-Assumptions!$C$24) | N8: =$G8*I8*(1-Assumptions!$C$25) | O8: =$G8*J8*(1-Assumptions!$C$26) | P8: =$G8*K8*(1-Assumptions!$C$27) | Q8: =SUM(M8:P8)
A9: WI-004 | B9: M1 | C9: Evaluation | D9: Basic deterministic evaluator behind the same evaluator-adapter pattern | E9: M | F9: =VLOOKUP($E9,Assumptions!$A$8:$C$11,3,FALSE) | G9: =$F9*(1+Assumptions!$C$21) | H9: 1 | I9: 0 | J9: 0 | K9: 0 | L9: =SUM(H9:K9) | M9: =$G9*H9*(1-Assumptions!$C$24) | N9: =$G9*I9*(1-Assumptions!$C$25) | O9: =$G9*J9*(1-Assumptions!$C$26) | P9: =$G9*K9*(1-Assumptions!$C$27) | Q9: =SUM(M9:P9)
A10: WI-005 | B10: M1 | C10: Connector | D10: LiteLLM pre-call connector, invoking input evaluation before model invocation | E10: L | F10: =VLOOKUP($E10,Assumptions!$A$8:$C$11,3,FALSE) | G10: =$F10*(1+Assumptions!$C$21) | H10: 1 | I10: 0 | J10: 0 | K10: 0 | L10: =SUM(H10:K10) | M10: =$G10*H10*(1-Assumptions!$C$24) | N10: =$G10*I10*(1-Assumptions!$C$25) | O10: =$G10*J10*(1-Assumptions!$C$26) | P10: =$G10*K10*(1-Assumptions!$C$27) | Q10: =SUM(M10:P10)
A11: WI-006 | B11: M1 | C11: Connector | D11: LiteLLM post-call connector, invoking output evaluation and applying safe output fallbacks | E11: L | F11: =VLOOKUP($E11,Assumptions!$A$8:$C$11,3,FALSE) | G11: =$F11*(1+Assumptions!$C$21) | H11: 1 | I11: 0 | J11: 0 | K11: 0 | L11: =SUM(H11:K11) | M11: =$G11*H11*(1-Assumptions!$C$24) | N11: =$G11*I11*(1-Assumptions!$C$25) | O11: =$G11*J11*(1-Assumptions!$C$26) | P11: =$G11*K11*(1-Assumptions!$C$27) | Q11: =SUM(M11:P11)
A12: WI-007 | B12: M1 | C12: Connector | D12: Conformance: connectors invoke the Evaluation API only — no policy logic, thresholds or detection rules embedded | E12: S | F12: =VLOOKUP($E12,Assumptions!$A$8:$C$11,3,FALSE) | G12: =$F12*(1+Assumptions!$C$21) | H12: 0.8 | I12: 0 | J12: 0.2 | K12: 0 | L12: =SUM(H12:K12) | M12: =$G12*H12*(1-Assumptions!$C$24) | N12: =$G12*I12*(1-Assumptions!$C$25) | O12: =$G12*J12*(1-Assumptions!$C$26) | P12: =$G12*K12*(1-Assumptions!$C$27) | Q12: =SUM(M12:P12)
A13: WI-008 | B13: M1 | C13: Runtime | D13: Observe mode implemented and made the default state for a new policy binding | E13: M | F13: =VLOOKUP($E13,Assumptions!$A$8:$C$11,3,FALSE) | G13: =$F13*(1+Assumptions!$C$21) | H13: 1 | I13: 0 | J13: 0 | K13: 0 | L13: =SUM(H13:K13) | M13: =$G13*H13*(1-Assumptions!$C$24) | N13: =$G13*I13*(1-Assumptions!$C$25) | O13: =$G13*J13*(1-Assumptions!$C$26) | P13: =$G13*K13*(1-Assumptions!$C$27) | Q13: =SUM(M13:P13)
A14: WI-009 | B14: M1 | C14: Audit | D14: Basic auditing: decision metadata logged for every evaluation — tenant, workload, policy version, stage, decision, reason codes, evaluator versions, timestamp, correlation identifier, retention flag | E14: L | F14: =VLOOKUP($E14,Assumptions!$A$8:$C$11,3,FALSE) | G14: =$F14*(1+Assumptions!$C$21) | H14: 1 | I14: 0 | J14: 0 | K14: 0 | L14: =SUM(H14:K14) | M14: =$G14*H14*(1-Assumptions!$C$24) | N14: =$G14*I14*(1-Assumptions!$C$25) | O14: =$G14*J14*(1-Assumptions!$C$26) | P14: =$G14*K14*(1-Assumptions!$C$27) | Q14: =SUM(M14:P14)
A15: WI-010 | B15: M1 | C15: Observability | D15: Evaluation latency measured per evaluation at P50, P95 and P99 | E15: M | F15: =VLOOKUP($E15,Assumptions!$A$8:$C$11,3,FALSE) | G15: =$F15*(1+Assumptions!$C$21) | H15: 0.6 | I15: 0.4 | J15: 0 | K15: 0 | L15: =SUM(H15:K15) | M15: =$G15*H15*(1-Assumptions!$C$24) | N15: =$G15*I15*(1-Assumptions!$C$25) | O15: =$G15*J15*(1-Assumptions!$C$26) | P15: =$G15*K15*(1-Assumptions!$C$27) | Q15: =SUM(M15:P15)
A16: WI-011 | B16: M1 | C16: Infrastructure | D16: Runtime deployed internally within the minimal account model — one non-production and one production account | E16: L | F16: =VLOOKUP($E16,Assumptions!$A$8:$C$11,3,FALSE) | G16: =$F16*(1+Assumptions!$C$21) | H16: 0.3 | I16: 0.7 | J16: 0 | K16: 0 | L16: =SUM(H16:K16) | M16: =$G16*H16*(1-Assumptions!$C$24) | N16: =$G16*I16*(1-Assumptions!$C$25) | O16: =$G16*J16*(1-Assumptions!$C$26) | P16: =$G16*K16*(1-Assumptions!$C$27) | Q16: =SUM(M16:P16)
A17: WI-012 | B17: M1 | C17: Infrastructure | D17: TLS on all runtime communication between connectors, the Evaluation API and evaluation engines | E17: S | F17: =VLOOKUP($E17,Assumptions!$A$8:$C$11,3,FALSE) | G17: =$F17*(1+Assumptions!$C$21) | H17: 0.2 | I17: 0.6 | J17: 0.2 | K17: 0 | L17: =SUM(H17:K17) | M17: =$G17*H17*(1-Assumptions!$C$24) | N17: =$G17*I17*(1-Assumptions!$C$25) | O17: =$G17*J17*(1-Assumptions!$C$26) | P17: =$G17*K17*(1-Assumptions!$C$27) | Q17: =SUM(M17:P17)
... A65: WI-060 | B65: M5 | C65: Integration | D65: Advanced authorization integration, without redefining a guardrail decision as a business-authorization decision | E65: L | F65: =VLOOKUP($E65,Assumptions!$A$8:$C$11,3,FALSE) | G65: =$F65*(1+Assumptions!$C$21) | H65: 0.7 | I65: 0 | J65: 0.3 | K65: 0 | L65: =SUM(H65:K65) | M65: =$G65*H65*(1-Assumptions!$C$24) | N65: =$G65*I65*(1-Assumptions!$C$25) | O65: =$G65*J65*(1-Assumptions!$C$26) | P65: =$G65*K65*(1-Assumptions!$C$27) | Q65: =SUM(M65:P65)
D66: Total | G66: =SUM(G6:G65) | M66: =SUM(M6:M65) | N66: =SUM(N6:N65) | O66: =SUM(O6:O65) | P66: =SUM(P6:P65) | Q66: =SUM(Q6:Q65)

Sheet Effort by role
A1: Effort by role
A2: Every cell is a formula over Work items and Assumptions. Milestone columns are net of each role's AI-assistance reduction; the two columns after the total show what that reduction removed.
A4: Role | B4: Name | C4: M1 | D4: M2 | E4: M3 | F4: M4 | G4: M5 | H4: Total days | I4: Before assist | J4: Removed | K4: AI assist | L4: Day rate | M4: Cost
A5: AIG | B5: AI Guardrails team | C5: =SUMIF('Work items'!$B$6:$B$65,"M1",'Work items'!$M$6:$M$65) | D5: =SUMIF('Work items'!$B$6:$B$65,"M2",'Work items'!$M$6:$M$65) | E5: =SUMIF('Work items'!$B$6:$B$65,"M3",'Work items'!$M$6:$M$65) | F5: =SUMIF('Work items'!$B$6:$B$65,"M4",'Work items'!$M$6:$M$65) | G5: =SUMIF('Work items'!$B$6:$B$65,"M5",'Work items'!$M$6:$M$65) | H5: =SUM(C5:G5) | I5: =SUMPRODUCT('Work items'!$G$6:$G$65,'Work items'!$H$6:$H$65) | J5: =I5-H5 | K5: =Assumptions!$C$24 | L5: =IF(Assumptions!$C$15="","",Assumptions!$C$15) | M5: =IF(Assumptions!$C$15="","",H5*Assumptions!$C$15)
A6: OPS | B6: Platform operations | C6: =SUMIF('Work items'!$B$6:$B$65,"M1",'Work items'!$N$6:$N$65) | D6: =SUMIF('Work items'!$B$6:$B$65,"M2",'Work items'!$N$6:$N$65) | E6: =SUMIF('Work items'!$B$6:$B$65,"M3",'Work items'!$N$6:$N$65) | F6: =SUMIF('Work items'!$B$6:$B$65,"M4",'Work items'!$N$6:$N$65) | G6: =SUMIF('Work items'!$B$6:$B$65,"M5",'Work items'!$N$6:$N$65) | H6: =SUM(C6:G6) | I6: =SUMPRODUCT('Work items'!$G$6:$G$65,'Work items'!$I$6:$I$65) | J6: =I6-H6 | K6: =Assumptions!$C$25 | L6: =IF(Assumptions!$C$16="","",Assumptions!$C$16) | M6: =IF(Assumptions!$C$16="","",H6*Assumptions!$C$16)
A7: SEC | B7: Security and governance | C7: =SUMIF('Work items'!$B$6:$B$65,"M1",'Work items'!$O$6:$O$65) | D7: =SUMIF('Work items'!$B$6:$B$65,"M2",'Work items'!$O$6:$O$65) | E7: =SUMIF('Work items'!$B$6:$B$65,"M3",'Work items'!$O$6:$O$65) | F7: =SUMIF('Work items'!$B$6:$B$65,"M4",'Work items'!$O$6:$O$65) | G7: =SUMIF('Work items'!$B$6:$B$65,"M5",'Work items'!$O$6:$O$65) | H7: =SUM(C7:G7) | I7: =SUMPRODUCT('Work items'!$G$6:$G$65,'Work items'!$J$6:$J$65) | J7: =I7-H7 | K7: =Assumptions!$C$26 | L7: =IF(Assumptions!$C$17="","",Assumptions!$C$17) | M7: =IF(Assumptions!$C$17="","",H7*Assumptions!$C$17)
A8: CONS | B8: Consuming teams | C8: =SUMIF('Work items'!$B$6:$B$65,"M1",'Work items'!$P$6:$P$65) | D8: =SUMIF('Work items'!$B$6:$B$65,"M2",'Work items'!$P$6:$P$65) | E8: =SUMIF('Work items'!$B$6:$B$65,"M3",'Work items'!$P$6:$P$65) | F8: =SUMIF('Work items'!$B$6:$B$65,"M4",'Work items'!$P$6:$P$65) | G8: =SUMIF('Work items'!$B$6:$B$65,"M5",'Work items'!$P$6:$P$65) | H8: =SUM(C8:G8) | I8: =SUMPRODUCT('Work items'!$G$6:$G$65,'Work items'!$K$6:$K$65) | J8: =I8-H8 | K8: =Assumptions!$C$27 | L8: =IF(Assumptions!$C$18="","",Assumptions!$C$18) | M8: =IF(Assumptions!$C$18="","",H8*Assumptions!$C$18)
B9: Total | C9: =SUM(C5:C8) | D9: =SUM(D5:D8) | E9: =SUM(E5:E8) | F9: =SUM(F5:F8) | G9: =SUM(G5:G8) | H9: =SUM(H5:H8) | I9: =SUM(I5:I8) | J9: =SUM(J5:J8) | M9: =IF(COUNT(Assumptions!$C$15:$C$18)=0,"",SUM(M5:M8))
A11: Cost stays blank until a day rate is set on Assumptions. With only some rates set, the total covers only those roles.

Sheet Effort by milestone
A1: Effort by milestone
A2: The same model rolled up the other way, net of AI assistance. Milestone order is dependency sequencing — it carries no dates and implies no schedule.
A4: Milestone | B4: Name | C4: Phase | D4: AIG days | E4: OPS days | F4: SEC days | G4: CONS days | H4: Total days | I4: Work items | J4: Cost
A5: M1 | B5: Integration proof | C5: Phase 1 | D5: =SUMIF('Work items'!$B$6:$B$65,$A5,'Work items'!$M$6:$M$65) | E5: =SUMIF('Work items'!$B$6:$B$65,$A5,'Work items'!$N$6:$N$65) | F5: =SUMIF('Work items'!$B$6:$B$65,$A5,'Work items'!$O$6:$O$65) | G5: =SUMIF('Work items'!$B$6:$B$65,$A5,'Work items'!$P$6:$P$65) | H5: =SUM(D5:G5) | I5: =COUNTIF('Work items'!$B$6:$B$65,$A5) | J5: =IF(COUNT(Assumptions!$C$15:$C$18)=0,"",D5*Assumptions!$C$15 + E5*Assumptions!$C$16 + F5*Assumptions!$C$17 + G5*Assumptions!$C$18)
A6: M2 | B6: Internal multi-team platform | C6: Phase 2 | D6: =SUMIF('Work items'!$B$6:$B$65,$A6,'Work items'!$M$6:$M$65) | E6: =SUMIF('Work items'!$B$6:$B$65,$A6,'Work items'!$N$6:$N$65) | F6: =SUMIF('Work items'!$B$6:$B$65,$A6,'Work items'!$O$6:$O$65) | G6: =SUMIF('Work items'!$B$6:$B$65,$A6,'Work items'!$P$6:$P$65) | H6: =SUM(D6:G6) | I6: =COUNTIF('Work items'!$B$6:$B$65,$A6) | J6: =IF(COUNT(Assumptions!$C$15:$C$18)=0,"",D6*Assumptions!$C$15 + E6*Assumptions!$C$16 + F6*Assumptions!$C$17 + G6*Assumptions!$C$18)
A7: M3 | B7: Guarded gateway | C7: Phase 3 | D7: =SUMIF('Work items'!$B$6:$B$65,$A7,'Work items'!$M$6:$M$65) | E7: =SUMIF('Work items'!$B$6:$B$65,$A7,'Work items'!$N$6:$N$65) | F7: =SUMIF('Work items'!$B$6:$B$65,$A7,'Work items'!$O$6:$O$65) | G7: =SUMIF('Work items'!$B$6:$B$65,$A7,'Work items'!$P$6:$P$65) | H7: =SUM(D7:G7) | I7: =COUNTIF('Work items'!$B$6:$B$65,$A7) | J7: =IF(COUNT(Assumptions!$C$15:$C$18)=0,"",D7*Assumptions!$C$15 + E7*Assumptions!$C$16 + F7*Assumptions!$C$17 + G7*Assumptions!$C$18)
A8: M4 | B8: Customer-managed runtime | C8: Phase 4 | D8: =SUMIF('Work items'!$B$6:$B$65,$A8,'Work items'!$M$6:$M$65) | E8: =SUMIF('Work items'!$B$6:$B$65,$A8,'Work items'!$N$6:$N$65) | F8: =SUMIF('Work items'!$B$6:$B$65,$A8,'Work items'!$O$6:$O$65) | G8: =SUMIF('Work items'!$B$6:$B$65,$A8,'Work items'!$P$6:$P$65) | H8: =SUM(D8:G8) | I8: =COUNTIF('Work items'!$B$6:$B$65,$A8) | J8: =IF(COUNT(Assumptions!$C$15:$C$18)=0,"",D8*Assumptions!$C$15 + E8*Assumptions!$C$16 + F8*Assumptions!$C$17 + G8*Assumptions!$C$18)
A9: M5 | B9: Advanced agent protection | C9: Phase 5 | D9: =SUMIF('Work items'!$B$6:$B$65,$A9,'Work items'!$M$6:$M$65) | E9: =SUMIF('Work items'!$B$6:$B$65,$A9,'Work items'!$N$6:$N$65) | F9: =SUMIF('Work items'!$B$6:$B$65,$A9,'Work items'!$O$6:$O$65) | G9: =SUMIF('Work items'!$B$6:$B$65,$A9,'Work items'!$P$6:$P$65) | H9: =SUM(D9:G9) | I9: =COUNTIF('Work items'!$B$6:$B$65,$A9) | J9: =IF(COUNT(Assumptions!$C$15:$C$18)=0,"",D9*Assumptions!$C$15 + E9*Assumptions!$C$16 + F9*Assumptions!$C$17 + G9*Assumptions!$C$18)
B10: Total | D10: =SUM(D5:D9) | E10: =SUM(E5:E9) | F10: =SUM(F5:F9) | G10: =SUM(G5:G9) | H10: =SUM(H5:H9) | I10: =SUM(I5:I9) | J10: =IF(COUNT(Assumptions!$C$15:$C$18)=0,"",SUM(J5:J9))
A12: M3–M5 lie beyond the Phase 1–2 validation gate. Their totals appear because the feature set is estimated across all five phases, not because the work may start.

Sheet Effort by workstream
A1: Effort by workstream
A2: Rolled up on the dimension the milestones cut across. Document order, not size order — a ranking that reshuffled on every edit would imply a stability this model does not have.
A4: Workstream | B4: Work items | C4: Days after assist | D4: Before assist | E4: Removed | F4: AIG days | G4: OPS days | H4: SEC days | I4: CONS days
A5: Contract | B5: =COUNTIF('Work items'!$C$6:$C$65,$A5) | C5: =SUMIF('Work items'!$C$6:$C$65,$A5,'Work items'!$Q$6:$Q$65) | D5: =SUMPRODUCT(('Work items'!$C$6:$C$65=$A5)*'Work items'!$G$6:$G$65*'Work items'!$H$6:$H$65) + SUMPRODUCT(('Work items'!$C$6:$C$65=$A5)*'Work items'!$G$6:$G$65*'Work items'!$I$6:$I$65) + SUMPRODUCT(('Work items'!$C$6:$C$65=$A5)*'Work items'!$G$6:$G$65*'Work items'!$J$6:$J$65) + SUMPRODUCT(('Work items'!$C$6:$C$65=$A5)*'Work items'!$G$6:$G$65*'Work items'!$K$6:$K$65) | E5: =D5-C5 | F5: =SUMIF('Work items'!$C$6:$C$65,$A5,'Work items'!$M$6:$M$65) | G5: =SUMIF('Work items'!$C$6:$C$65,$A5,'Work items'!$N$6:$N$65) | H5: =SUMIF('Work items'!$C$6:$C$65,$A5,'Work items'!$O$6:$O$65) | I5: =SUMIF('Work items'!$C$6:$C$65,$A5,'Work items'!$P$6:$P$65)
A6: Evaluation | B6: =COUNTIF('Work items'!$C$6:$C$65,$A6) | C6: =SUMIF('Work items'!$C$6:$C$65,$A6,'Work items'!$Q$6:$Q$65) | D6: =SUMPRODUCT(('Work items'!$C$6:$C$65=$A6)*'Work items'!$G$6:$G$65*'Work items'!$H$6:$H$65) + SUMPRODUCT(('Work items'!$C$6:$C$65=$A6)*'Work items'!$G$6:$G$65*'Work items'!$I$6:$I$65) + SUMPRODUCT(('Work items'!$C$6:$C$65=$A6)*'Work items'!$G$6:$G$65*'Work items'!$J$6:$J$65) + SUMPRODUCT(('Work items'!$C$6:$C$65=$A6)*'Work items'!$G$6:$G$65*'Work items'!$K$6:$K$65) | E6: =D6-C6 | F6: =SUMIF('Work items'!$C$6:$C$65,$A6,'Work items'!$M$6:$M$65) | G6: =SUMIF('Work items'!$C$6:$C$65,$A6,'Work items'!$N$6:$N$65) | H6: =SUMIF('Work items'!$C$6:$C$65,$A6,'Work items'!$O$6:$O$65) | I6: =SUMIF('Work items'!$C$6:$C$65,$A6,'Work items'!$P$6:$P$65)
A7: Connector | B7: =COUNTIF('Work items'!$C$6:$C$65,$A7) | C7: =SUMIF('Work items'!$C$6:$C$65,$A7,'Work items'!$Q$6:$Q$65) | D7: =SUMPRODUCT(('Work items'!$C$6:$C$65=$A7)*'Work items'!$G$6:$G$65*'Work items'!$H$6:$H$65) + SUMPRODUCT(('Work items'!$C$6:$C$65=$A7)*'Work items'!$G$6:$G$65*'Work items'!$I$6:$I$65) + SUMPRODUCT(('Work items'!$C$6:$C$65=$A7)*'Work items'!$G$6:$G$65*'Work items'!$J$6:$J$65) + SUMPRODUCT(('Work items'!$C$6:$C$65=$A7)*'Work items'!$G$6:$G$65*'Work items'!$K$6:$K$65) | E7: =D7-C7 | F7: =SUMIF('Work items'!$C$6:$C$65,$A7,'Work items'!$M$6:$M$65) | G7: =SUMIF('Work items'!$C$6:$C$65,$A7,'Work items'!$N$6:$N$65) | H7: =SUMIF('Work items'!$C$6:$C$65,$A7,'Work items'!$O$6:$O$65) | I7: =SUMIF('Work items'!$C$6:$C$65,$A7,'Work items'!$P$6:$P$65)
A8: Runtime | B8: =COUNTIF('Work items'!$C$6:$C$65,$A8) | C8: =SUMIF('Work items'!$C$6:$C$65,$A8,'Work items'!$Q$6:$Q$65) | D8: =SUMPRODUCT(('Work items'!$C$6:$C$65=$A8)*'Work items'!$G$6:$G$65*'Work items'!$H$6:$H$65) + SUMPRODUCT(('Work items'!$C$6:$C$65=$A8)*'Work items'!$G$6:$G$65*'Work items'!$I$6:$I$65) + SUMPRODUCT(('Work items'!$C$6:$C$65=$A8)*'Work items'!$G$6:$G$65*'Work items'!$J$6:$J$65) + SUMPRODUCT(('Work items'!$C$6:$C$65=$A8)*'Work items'!$G$6:$G$65*'Work items'!$K$6:$K$65) | E8: =D8-C8 | F8: =SUMIF('Work items'!$C$6:$C$65,$A8,'Work items'!$M$6:$M$65) | G8: =SUMIF('Work items'!$C$6:$C$65,$A8,'Work items'!$N$6:$N$65) | H8: =SUMIF('Work items'!$C$6:$C$65,$A8,'Work items'!$O$6:$O$65) | I8: =SUMIF('Work items'!$C$6:$C$65,$A8,'Work items'!$P$6:$P$65)
A9: Audit | B9: =COUNTIF('Work items'!$C$6:$C$65,$A9) | C9: =SUMIF('Work items'!$C$6:$C$65,$A9,'Work items'!$Q$6:$Q$65) | D9: =SUMPRODUCT(('Work items'!$C$6:$C$65=$A9)*'Work items'!$G$6:$G$65*'Work items'!$H$6:$H$65) + SUMPRODUCT(('Work items'!$C$6:$C$65=$A9)*'Work items'!$G$6:$G$65*'Work items'!$I$6:$I$65) + SUMPRODUCT(('Work items'!$C$6:$C$65=$A9)*'Work items'!$G$6:$G$65*'Work items'!$J$6:$J$65) + SUMPRODUCT(('Work items'!$C$6:$C$65=$A9)*'Work items'!$G$6:$G$65*'Work items'!$K$6:$K$65) | E9: =D9-C9 | F9: =SUMIF('Work items'!$C$6:$C$65,$A9,'Work items'!$M$6:$M$65) | G9: =SUMIF('Work items'!$C$6:$C$65,$A9,'Work items'!$N$6:$N$65) | H9: =SUMIF('Work items'!$C$6:$C$65,$A9,'Work items'!$O$6:$O$65) | I9: =SUMIF('Work items'!$C$6:$C$65,$A9,'Work items'!$P$6:$P$65)
A10: Observability | B10: =COUNTIF('Work items'!$C$6:$C$65,$A10) | C10: =SUMIF('Work items'!$C$6:$C$65,$A10,'Work items'!$Q$6:$Q$65) | D10: =SUMPRODUCT(('Work items'!$C$6:$C$65=$A10)*'Work items'!$G$6:$G$65*'Work items'!$H$6:$H$65) + SUMPRODUCT(('Work items'!$C$6:$C$65=$A10)*'Work items'!$G$6:$G$65*'Work items'!$I$6:$I$65) + SUMPRODUCT(('Work items'!$C$6:$C$65=$A10)*'Work items'!$G$6:$G$65*'Work items'!$J$6:$J$65) + SUMPRODUCT(('Work items'!$C$6:$C$65=$A10)*'Work items'!$G$6:$G$65*'Work items'!$K$6:$K$65) | E10: =D10-C10 | F10: =SUMIF('Work items'!$C$6:$C$65,$A10,'Work items'!$M$6:$M$65) | G10: =SUMIF('Work items'!$C$6:$C$65,$A10,'Work items'!$N$6:$N$65) | H10: =SUMIF('Work items'!$C$6:$C$65,$A10,'Work items'!$O$6:$O$65) | I10: =SUMIF('Work items'!$C$6:$C$65,$A10,'Work items'!$P$6:$P$65)
A11: Infrastructure | B11: =COUNTIF('Work items'!$C$6:$C$65,$A11) | C11: =SUMIF('Work items'!$C$6:$C$65,$A11,'Work items'!$Q$6:$Q$65) | D11: =SUMPRODUCT(('Work items'!$C$6:$C$65=$A11)*'Work items'!$G$6:$G$65*'Work items'!$H$6:$H$65) + SUMPRODUCT(('Work items'!$C$6:$C$65=$A11)*'Work items'!$G$6:$G$65*'Work items'!$I$6:$I$65) + SUMPRODUCT(('Work items'!$C$6:$C$65=$A11)*'Work items'!$G$6:$G$65*'Work items'!$J$6:$J$65) + SUMPRODUCT(('Work items'!$C$6:$C$65=$A11)*'Work items'!$G$6:$G$65*'Work items'!$K$6:$K$65) | E11: =D11-C11 | F11: =SUMIF('Work items'!$C$6:$C$65,$A11,'Work items'!$M$6:$M$65) | G11: =SUMIF('Work items'!$C$6:$C$65,$A11,'Work items'!$N$6:$N$65) | H11: =SUMIF('Work items'!$C$6:$C$65,$A11,'Work items'!$O$6:$O$65) | I11: =SUMIF('Work items'!$C$6:$C$65,$A11,'Work items'!$P$6:$P$65)
A12: Validation | B12: =COUNTIF('Work items'!$C$6:$C$65,$A12) | C12: =SUMIF('Work items'!$C$6:$C$65,$A12,'Work items'!$Q$6:$Q$65) | D12: =SUMPRODUCT(('Work items'!$C$6:$C$65=$A12)*'Work items'!$G$6:$G$65*'Work items'!$H$6:$H$65) + SUMPRODUCT(('Work items'!$C$6:$C$65=$A12)*'Work items'!$G$6:$G$65*'Work items'!$I$6:$I$65) + SUMPRODUCT(('Work items'!$C$6:$C$65=$A12)*'Work items'!$G$6:$G$65*'Work items'!$J$6:$J$65) + SUMPRODUCT(('Work items'!$C$6:$C$65=$A12)*'Work items'!$G$6:$G$65*'Work items'!$K$6:$K$65) | E12: =D12-C12 | F12: =SUMIF('Work items'!$C$6:$C$65,$A12,'Work items'!$M$6:$M$65) | G12: =SUMIF('Work items'!$C$6:$C$65,$A12,'Work items'!$N$6:$N$65) | H12: =SUMIF('Work items'!$C$6:$C$65,$A12,'Work items'!$O$6:$O$65) | I12: =SUMIF('Work items'!$C$6:$C$65,$A12,'Work items'!$P$6:$P$65)
A13: Packaging | B13: =COUNTIF('Work items'!$C$6:$C$65,$A13) | C13: =SUMIF('Work items'!$C$6:$C$65,$A13,'Work items'!$Q$6:$Q$65) | D13: =SUMPRODUCT(('Work items'!$C$6:$C$65=$A13)*'Work items'!$G$6:$G$65*'Work items'!$H$6:$H$65) + SUMPRODUCT(('Work items'!$C$6:$C$65=$A13)*'Work items'!$G$6:$G$65*'Work items'!$I$6:$I$65) + SUMPRODUCT(('Work items'!$C$6:$C$65=$A13)*'Work items'!$G$6:$G$65*'Work items'!$J$6:$J$65) + SUMPRODUCT(('Work items'!$C$6:$C$65=$A13)*'Work items'!$G$6:$G$65*'Work items'!$K$6:$K$65) | E13: =D13-C13 | F13: =SUMIF('Work items'!$C$6:$C$65,$A13,'Work items'!$M$6:$M$65) | G13: =SUMIF('Work items'!$C$6:$C$65,$A13,'Work items'!$N$6:$N$65) | H13: =SUMIF('Work items'!$C$6:$C$65,$A13,'Work items'!$O$6:$O$65) | I13: =SUMIF('Work items'!$C$6:$C$65,$A13,'Work items'!$P$6:$P$65)
A14: Control plane | B14: =COUNTIF('Work items'!$C$6:$C$65,$A14) | C14: =SUMIF('Work items'!$C$6:$C$65,$A14,'Work items'!$Q$6:$Q$65) | D14: =SUMPRODUCT(('Work items'!$C$6:$C$65=$A14)*'Work items'!$G$6:$G$65*'Work items'!$H$6:$H$65) + SUMPRODUCT(('Work items'!$C$6:$C$65=$A14)*'Work items'!$G$6:$G$65*'Work items'!$I$6:$I$65) + SUMPRODUCT(('Work items'!$C$6:$C$65=$A14)*'Work items'!$G$6:$G$65*'Work items'!$J$6:$J$65) + SUMPRODUCT(('Work items'!$C$6:$C$65=$A14)*'Work items'!$G$6:$G$65*'Work items'!$K$6:$K$65) | E14: =D14-C14 | F14: =SUMIF('Work items'!$C$6:$C$65,$A14,'Work items'!$M$6:$M$65) | G14: =SUMIF('Work items'!$C$6:$C$65,$A14,'Work items'!$N$6:$N$65) | H14: =SUMIF('Work items'!$C$6:$C$65,$A14,'Work items'!$O$6:$O$65) | I14: =SUMIF('Work items'!$C$6:$C$65,$A14,'Work items'!$P$6:$P$65)
A15: Security | B15: =COUNTIF('Work items'!$C$6:$C$65,$A15) | C15: =SUMIF('Work items'!$C$6:$C$65,$A15,'Work items'!$Q$6:$Q$65) | D15: =SUMPRODUCT(('Work items'!$C$6:$C$65=$A15)*'Work items'!$G$6:$G$65*'Work items'!$H$6:$H$65) + SUMPRODUCT(('Work items'!$C$6:$C$65=$A15)*'Work items'!$G$6:$G$65*'Work items'!$I$6:$I$65) + SUMPRODUCT(('Work items'!$C$6:$C$65=$A15)*'Work items'!$G$6:$G$65*'Work items'!$J$6:$J$65) + SUMPRODUCT(('Work items'!$C$6:$C$65=$A15)*'Work items'!$G$6:$G$65*'Work items'!$K$6:$K$65) | E15: =D15-C15 | F15: =SUMIF('Work items'!$C$6:$C$65,$A15,'Work items'!$M$6:$M$65) | G15: =SUMIF('Work items'!$C$6:$C$65,$A15,'Work items'!$N$6:$N$65) | H15: =SUMIF('Work items'!$C$6:$C$65,$A15,'Work items'!$O$6:$O$65) | I15: =SUMIF('Work items'!$C$6:$C$65,$A15,'Work items'!$P$6:$P$65)
A16: Gateway | B16: =COUNTIF('Work items'!$C$6:$C$65,$A16) | C16: =SUMIF('Work items'!$C$6:$C$65,$A16,'Work items'!$Q$6:$Q$65) | D16: =SUMPRODUCT(('Work items'!$C$6:$C$65=$A16)*'Work items'!$G$6:$G$65*'Work items'!$H$6:$H$65) + SUMPRODUCT(('Work items'!$C$6:$C$65=$A16)*'Work items'!$G$6:$G$65*'Work items'!$I$6:$I$65) + SUMPRODUCT(('Work items'!$C$6:$C$65=$A16)*'Work items'!$G$6:$G$65*'Work items'!$J$6:$J$65) + SUMPRODUCT(('Work items'!$C$6:$C$65=$A16)*'Work items'!$G$6:$G$65*'Work items'!$K$6:$K$65) | E16: =D16-C16 | F16: =SUMIF('Work items'!$C$6:$C$65,$A16,'Work items'!$M$6:$M$65) | G16: =SUMIF('Work items'!$C$6:$C$65,$A16,'Work items'!$N$6:$N$65) | H16: =SUMIF('Work items'!$C$6:$C$65,$A16,'Work items'!$O$6:$O$65) | I16: =SUMIF('Work items'!$C$6:$C$65,$A16,'Work items'!$P$6:$P$65)
... A19: Integration | B19: =COUNTIF('Work items'!$C$6:$C$65,$A19) | C19: =SUMIF('Work items'!$C$6:$C$65,$A19,'Work items'!$Q$6:$Q$65) | D19: =SUMPRODUCT(('Work items'!$C$6:$C$65=$A19)*'Work items'!$G$6:$G$65*'Work items'!$H$6:$H$65) + SUMPRODUCT(('Work items'!$C$6:$C$65=$A19)*'Work items'!$G$6:$G$65*'Work items'!$I$6:$I$65) + SUMPRODUCT(('Work items'!$C$6:$C$65=$A19)*'Work items'!$G$6:$G$65*'Work items'!$J$6:$J$65) + SUMPRODUCT(('Work items'!$C$6:$C$65=$A19)*'Work items'!$G$6:$G$65*'Work items'!$K$6:$K$65) | E19: =D19-C19 | F19: =SUMIF('Work items'!$C$6:$C$65,$A19,'Work items'!$M$6:$M$65) | G19: =SUMIF('Work items'!$C$6:$C$65,$A19,'Work items'!$N$6:$N$65) | H19: =SUMIF('Work items'!$C$6:$C$65,$A19,'Work items'!$O$6:$O$65) | I19: =SUMIF('Work items'!$C$6:$C$65,$A19,'Work items'!$P$6:$P$65)
A20: Total | B20: =SUM(B5:B19) | C20: =SUM(C5:C19) | D20: =SUM(D5:D19) | E20: =SUM(E5:E19) | F20: =SUM(F5:F19) | G20: =SUM(G5:G19) | H20: =SUM(H5:H19) | I20: =SUM(I5:I19)

Sheet Sensitivity
A1: Sensitivity
A2: Total person-days as the two knobs move. The contingency column here is local to this sheet and does not change Assumptions; the assistance multiplier scales every role's factor at once.
A4: Base days, no contingency, no assistance | B4: AIG | C4: OPS | D4: SEC | E4: CONS
A5: Per role | B5: =SUMPRODUCT('Work items'!$F$6:$F$65,'Work items'!$H$6:$H$65) | C5: =SUMPRODUCT('Work items'!$F$6:$F$65,'Work items'!$I$6:$I$65) | D5: =SUMPRODUCT('Work items'!$F$6:$F$65,'Work items'!$J$6:$J$65) | E5: =SUMPRODUCT('Work items'!$F$6:$F$65,'Work items'!$K$6:$K$65)
A8: Contingency | B8: No assistance | C8: Half the assumed | D8: The assumed factors
A9: 0 | B9: =(1+$A9)*(B$5*(1-Assumptions!$C$24*0.0) + C$5*(1-Assumptions!$C$25*0.0) + D$5*(1-Assumptions!$C$26*0.0) + E$5*(1-Assumptions!$C$27*0.0)) | C9: =(1+$A9)*(B$5*(1-Assumptions!$C$24*0.5) + C$5*(1-Assumptions!$C$25*0.5) + D$5*(1-Assumptions!$C$26*0.5) + E$5*(1-Assumptions!$C$27*0.5)) | D9: =(1+$A9)*(B$5*(1-Assumptions!$C$24*1.0) + C$5*(1-Assumptions!$C$25*1.0) + D$5*(1-Assumptions!$C$26*1.0) + E$5*(1-Assumptions!$C$27*1.0))
A10: 0.05 | B10: =(1+$A10)*(B$5*(1-Assumptions!$C$24*0.0) + C$5*(1-Assumptions!$C$25*0.0) + D$5*(1-Assumptions!$C$26*0.0) + E$5*(1-Assumptions!$C$27*0.0)) | C10: =(1+$A10)*(B$5*(1-Assumptions!$C$24*0.5) + C$5*(1-Assumptions!$C$25*0.5) + D$5*(1-Assumptions!$C$26*0.5) + E$5*(1-Assumptions!$C$27*0.5)) | D10: =(1+$A10)*(B$5*(1-Assumptions!$C$24*1.0) + C$5*(1-Assumptions!$C$25*1.0) + D$5*(1-Assumptions!$C$26*1.0) + E$5*(1-Assumptions!$C$27*1.0))
A11: 0.1 | B11: =(1+$A11)*(B$5*(1-Assumptions!$C$24*0.0) + C$5*(1-Assumptions!$C$25*0.0) + D$5*(1-Assumptions!$C$26*0.0) + E$5*(1-Assumptions!$C$27*0.0)) | C11: =(1+$A11)*(B$5*(1-Assumptions!$C$24*0.5) + C$5*(1-Assumptions!$C$25*0.5) + D$5*(1-Assumptions!$C$26*0.5) + E$5*(1-Assumptions!$C$27*0.5)) | D11: =(1+$A11)*(B$5*(1-Assumptions!$C$24*1.0) + C$5*(1-Assumptions!$C$25*1.0) + D$5*(1-Assumptions!$C$26*1.0) + E$5*(1-Assumptions!$C$27*1.0))
A12: 0.15 | B12: =(1+$A12)*(B$5*(1-Assumptions!$C$24*0.0) + C$5*(1-Assumptions!$C$25*0.0) + D$5*(1-Assumptions!$C$26*0.0) + E$5*(1-Assumptions!$C$27*0.0)) | C12: =(1+$A12)*(B$5*(1-Assumptions!$C$24*0.5) + C$5*(1-Assumptions!$C$25*0.5) + D$5*(1-Assumptions!$C$26*0.5) + E$5*(1-Assumptions!$C$27*0.5)) | D12: =(1+$A12)*(B$5*(1-Assumptions!$C$24*1.0) + C$5*(1-Assumptions!$C$25*1.0) + D$5*(1-Assumptions!$C$26*1.0) + E$5*(1-Assumptions!$C$27*1.0))
A13: 0.2 | B13: =(1+$A13)*(B$5*(1-Assumptions!$C$24*0.0) + C$5*(1-Assumptions!$C$25*0.0) + D$5*(1-Assumptions!$C$26*0.0) + E$5*(1-Assumptions!$C$27*0.0)) | C13: =(1+$A13)*(B$5*(1-Assumptions!$C$24*0.5) + C$5*(1-Assumptions!$C$25*0.5) + D$5*(1-Assumptions!$C$26*0.5) + E$5*(1-Assumptions!$C$27*0.5)) | D13: =(1+$A13)*(B$5*(1-Assumptions!$C$24*1.0) + C$5*(1-Assumptions!$C$25*1.0) + D$5*(1-Assumptions!$C$26*1.0) + E$5*(1-Assumptions!$C$27*1.0))
A14: 0.25 | B14: =(1+$A14)*(B$5*(1-Assumptions!$C$24*0.0) + C$5*(1-Assumptions!$C$25*0.0) + D$5*(1-Assumptions!$C$26*0.0) + E$5*(1-Assumptions!$C$27*0.0)) | C14: =(1+$A14)*(B$5*(1-Assumptions!$C$24*0.5) + C$5*(1-Assumptions!$C$25*0.5) + D$5*(1-Assumptions!$C$26*0.5) + E$5*(1-Assumptions!$C$27*0.5)) | D14: =(1+$A14)*(B$5*(1-Assumptions!$C$24*1.0) + C$5*(1-Assumptions!$C$25*1.0) + D$5*(1-Assumptions!$C$26*1.0) + E$5*(1-Assumptions!$C$27*1.0))
A32: The spread across this grid is wider than any difference the model's role splits produce. Argue about these two numbers first.

Sheet Pivot data
A1: Pivot data
A2: Every work item, once per role. Insert → PivotTable over this sheet and slice it any way the rollups do not. Rows with a zero share are kept so the grain stays rectangular.
A4: Work item | B4: Milestone | C4: Phase | D4: Workstream | E4: Size | F4: Role | G4: Share | H4: Days before assist | I4: Days after assist | J4: Description
A5: WI-001 | B5: M1 | C5: Phase 1 | D5: Contract | E5: L | F5: AIG | G5: ='Work items'!H6 | H5: ='Work items'!G6*'Work items'!H6 | I5: ='Work items'!M6 | J5: Evaluation contract defined and published — request structure, decision structure, reason codes, policy-version semantics, expressed independently of any gateway or vendor
A6: WI-001 | B6: M1 | C6: Phase 1 | D6: Contract | E6: L | F6: OPS | G6: ='Work items'!I6 | H6: ='Work items'!G6*'Work items'!I6 | I6: ='Work items'!N6 | J6: Evaluation contract defined and published — request structure, decision structure, reason codes, policy-version semantics, expressed independently of any gateway or vendor
A7: WI-001 | B7: M1 | C7: Phase 1 | D7: Contract | E7: L | F7: SEC | G7: ='Work items'!J6 | H7: ='Work items'!G6*'Work items'!J6 | I7: ='Work items'!O6 | J7: Evaluation contract defined and published — request structure, decision structure, reason codes, policy-version semantics, expressed independently of any gateway or vendor
A8: WI-001 | B8: M1 | C8: Phase 1 | D8: Contract | E8: L | F8: CONS | G8: ='Work items'!K6 | H8: ='Work items'!G6*'Work items'!K6 | I8: ='Work items'!P6 | J8: Evaluation contract defined and published — request structure, decision structure, reason codes, policy-version semantics, expressed independently of any gateway or vendor
A9: WI-002 | B9: M1 | C9: Phase 1 | D9: Contract | E9: L | F9: AIG | G9: ='Work items'!H7 | H9: ='Work items'!G7*'Work items'!H7 | I9: ='Work items'!M7 | J9: Guardrail policy format defined as a versioned, vendor-independent schema
A10: WI-002 | B10: M1 | C10: Phase 1 | D10: Contract | E10: L | F10: OPS | G10: ='Work items'!I7 | H10: ='Work items'!G7*'Work items'!I7 | I10: ='Work items'!N7 | J10: Guardrail policy format defined as a versioned, vendor-independent schema
A11: WI-002 | B11: M1 | C11: Phase 1 | D11: Contract | E11: L | F11: SEC | G11: ='Work items'!J7 | H11: ='Work items'!G7*'Work items'!J7 | I11: ='Work items'!O7 | J11: Guardrail policy format defined as a versioned, vendor-independent schema
A12: WI-002 | B12: M1 | C12: Phase 1 | D12: Contract | E12: L | F12: CONS | G12: ='Work items'!K7 | H12: ='Work items'!G7*'Work items'!K7 | I12: ='Work items'!P7 | J12: Guardrail policy format defined as a versioned, vendor-independent schema
A13: WI-003 | B13: M1 | C13: Phase 1 | D13: Evaluation | E13: L | F13: AIG | G13: ='Work items'!H8 | H13: ='Work items'!G8*'Work items'!H8 | I13: ='Work items'!M8 | J13: Amazon Bedrock Guardrails adapter, normalizing vendor responses into the platform's own decision structure before they reach any policy or connector
A14: WI-003 | B14: M1 | C14: Phase 1 | D14: Evaluation | E14: L | F14: OPS | G14: ='Work items'!I8 | H14: ='Work items'!G8*'Work items'!I8 | I14: ='Work items'!N8 | J14: Amazon Bedrock Guardrails adapter, normalizing vendor responses into the platform's own decision structure before they reach any policy or connector
A15: WI-003 | B15: M1 | C15: Phase 1 | D15: Evaluation | E15: L | F15: SEC | G15: ='Work items'!J8 | H15: ='Work items'!G8*'Work items'!J8 | I15: ='Work items'!O8 | J15: Amazon Bedrock Guardrails adapter, normalizing vendor responses into the platform's own decision structure before they reach any policy or connector
A16: WI-003 | B16: M1 | C16: Phase 1 | D16: Evaluation | E16: L | F16: CONS | G16: ='Work items'!K8 | H16: ='Work items'!G8*'Work items'!K8 | I16: ='Work items'!P8 | J16: Amazon Bedrock Guardrails adapter, normalizing vendor responses into the platform's own decision structure before they reach any policy or connector
A17: WI-004 | B17: M1 | C17: Phase 1 | D17: Evaluation | E17: M | F17: AIG | G17: ='Work items'!H9 | H17: ='Work items'!G9*'Work items'!H9 | I17: ='Work items'!M9 | J17: Basic deterministic evaluator behind the same evaluator-adapter pattern
A18: WI-004 | B18: M1 | C18: Phase 1 | D18: Evaluation | E18: M | F18: OPS | G18: ='Work items'!I9 | H18: ='Work items'!G9*'Work items'!I9 | I18: ='Work items'!N9 | J18: Basic deterministic evaluator behind the same evaluator-adapter pattern
A19: WI-004 | B19: M1 | C19: Phase 1 | D19: Evaluation | E19: M | F19: SEC | G19: ='Work items'!J9 | H19: ='Work items'!G9*'Work items'!J9 | I19: ='Work items'!O9 | J19: Basic deterministic evaluator behind the same evaluator-adapter pattern
A20: WI-004 | B20: M1 | C20: Phase 1 | D20: Evaluation | E20: M | F20: CONS | G20: ='Work items'!K9 | H20: ='Work items'!G9*'Work items'!K9 | I20: ='Work items'!P9 | J20: Basic deterministic evaluator behind the same evaluator-adapter pattern
A21: WI-005 | B21: M1 | C21: Phase 1 | D21: Connector | E21: L | F21: AIG | G21: ='Work items'!H10 | H21: ='Work items'!G10*'Work items'!H10 | I21: ='Work items'!M10 | J21: LiteLLM pre-call connector, invoking input evaluation before model invocation
A22: WI-005 | B22: M1 | C22: Phase 1 | D22: Connector | E22: L | F22: OPS | G22: ='Work items'!I10 | H22: ='Work items'!G10*'Work items'!I10 | I22: ='Work items'!N10 | J22: LiteLLM pre-call connector, invoking input evaluation before model invocation
A23: WI-005 | B23: M1 | C23: Phase 1 | D23: Connector | E23: L | F23: SEC | G23: ='Work items'!J10 | H23: ='Work items'!G10*'Work items'!J10 | I23: ='Work items'!O10 | J23: LiteLLM pre-call connector, invoking input evaluation before model invocation
A24: WI-005 | B24: M1 | C24: Phase 1 | D24: Connector | E24: L | F24: CONS | G24: ='Work items'!K10 | H24: ='Work items'!G10*'Work items'!K10 | I24: ='Work items'!P10 | J24: LiteLLM pre-call connector, invoking input evaluation before model invocation
A25: WI-006 | B25: M1 | C25: Phase 1 | D25: Connector | E25: L | F25: AIG | G25: ='Work items'!H11 | H25: ='Work items'!G11*'Work items'!H11 | I25: ='Work items'!M11 | J25: LiteLLM post-call connector, invoking output evaluation and applying safe output fallbacks
A26: WI-006 | B26: M1 | C26: Phase 1 | D26: Connector | E26: L | F26: OPS | G26: ='Work items'!I11 | H26: ='Work items'!G11*'Work items'!I11 | I26: ='Work items'!N11 | J26: LiteLLM post-call connector, invoking output evaluation and applying safe output fallbacks
A27: WI-006 | B27: M1 | C27: Phase 1 | D27: Connector | E27: L | F27: SEC | G27: ='Work items'!J11 | H27: ='Work items'!G11*'Work items'!J11 | I27: ='Work items'!O11 | J27: LiteLLM post-call connector, invoking output evaluation and applying safe output fallbacks
A28: WI-006 | B28: M1 | C28: Phase 1 | D28: Connector | E28: L | F28: CONS | G28: ='Work items'!K11 | H28: ='Work items'!G11*'Work items'!K11 | I28: ='Work items'!P11 | J28: LiteLLM post-call connector, invoking output evaluation and applying safe output fallbacks
A29: WI-007 | B29: M1 | C29: Phase 1 | D29: Connector | E29: S | F29: AIG | G29: ='Work items'!H12 | H29: ='Work items'!G12*'Work items'!H12 | I29: ='Work items'!M12 | J29: Conformance: connectors invoke the Evaluation API only — no policy logic, thresholds or detection rules embedded
A30: WI-007 | B30: M1 | C30: Phase 1 | D30: Connector | E30: S | F30: OPS | G30: ='Work items'!I12 | H30: ='Work items'!G12*'Work items'!I12 | I30: ='Work items'!N12 | J30: Conformance: connectors invoke the Evaluation API only — no policy logic, thresholds or detection rules embedded
A31: WI-007 | B31: M1 | C31: Phase 1 | D31: Connector | E31: S | F31: SEC | G31: ='Work items'!J12 | H31: ='Work items'!G12*'Work items'!J12 | I31: ='Work items'!O12 | J31: Conformance: connectors invoke the Evaluation API only — no policy logic, thresholds or detection rules embedded
A32: WI-007 | B32: M1 | C32: Phase 1 | D32: Connector | E32: S | F32: CONS | G32: ='Work items'!K12 | H32: ='Work items'!G12*'Work items'!K12 | I32: ='Work items'!P12 | J32: Conformance: connectors invoke the Evaluation API only — no policy logic, thresholds or detection rules embedded
A33: WI-008 | B33: M1 | C33: Phase 1 | D33: Runtime | E33: M | F33: AIG | G33: ='Work items'!H13 | H33: ='Work items'!G13*'Work items'!H13 | I33: ='Work items'!M13 | J33: Observe mode implemented and made the default state for a new policy binding
A34: WI-008 | B34: M1 | C34: Phase 1 | D34: Runtime | E34: M | F34: OPS | G34: ='Work items'!I13 | H34: ='Work items'!G13*'Work items'!I13 | I34: ='Work items'!N13 | J34: Observe mode implemented and made the default state for a new policy binding
A35: WI-008 | B35: M1 | C35: Phase 1 | D35: Runtime | E35: M | F35: SEC | G35: ='Work items'!J13 | H35: ='Work items'!G13*'Work items'!J13 | I35: ='Work items'!O13 | J35: Observe mode implemented and made the default state for a new policy binding
A36: WI-008 | B36: M1 | C36: Phase 1 | D36: Runtime | E36: M | F36: CONS | G36: ='Work items'!K13 | H36: ='Work items'!G13*'Work items'!K13 | I36: ='Work items'!P13 | J36: Observe mode implemented and made the default state for a new policy binding
A37: WI-009 | B37: M1 | C37: Phase 1 | D37: Audit | E37: L | F37: AIG | G37: ='Work items'!H14 | H37: ='Work items'!G14*'Work items'!H14 | I37: ='Work items'!M14 | J37: Basic auditing: decision metadata logged for every evaluation — tenant, workload, policy version, stage, decision, reason codes, evaluator versions, timestamp, correlation identifier, retention flag
A38: WI-009 | B38: M1 | C38: Phase 1 | D38: Audit | E38: L | F38: OPS | G38: ='Work items'!I14 | H38: ='Work items'!G14*'Work items'!I14 | I38: ='Work items'!N14 | J38: Basic auditing: decision metadata logged for every evaluation — tenant, workload, policy version, stage, decision, reason codes, evaluator versions, timestamp, correlation identifier, retention flag
A39: WI-009 | B39: M1 | C39: Phase 1 | D39: Audit | E39: L | F39: SEC | G39: ='Work items'!J14 | H39: ='Work items'!G14*'Work items'!J14 | I39: ='Work items'!O14 | J39: Basic auditing: decision metadata logged for every evaluation — tenant, workload, policy version, stage, decision, reason codes, evaluator versions, timestamp, correlation identifier, retention flag
A40: WI-009 | B40: M1 | C40: Phase 1 | D40: Audit | E40: L | F40: CONS | G40: ='Work items'!K14 | H40: ='Work items'!G14*'Work items'!K14 | I40: ='Work items'!P14 | J40: Basic auditing: decision metadata logged for every evaluation — tenant, workload, policy version, stage, decision, reason codes, evaluator versions, timestamp, correlation identifier, retention flag
A41: WI-010 | B41: M1 | C41: Phase 1 | D41: Observability | E41: M | F41: AIG | G41: ='Work items'!H15 | H41: ='Work items'!G15*'Work items'!H15 | I41: ='Work items'!M15 | J41: Evaluation latency measured per evaluation at P50, P95 and P99
...

Sheet Roadmap
A1: Roadmap
A2: Dependency sequencing, not scheduling. No calendar dates or durations exist in the source material and none are invented here.
A4: Milestone | B4: Name | C4: Phase | D4: Primary deployment mode | E4: Objective | F4: Entry condition
A5: M1 | B5: Integration proof | C5: Phase 1 | D5: Mode A — Remote Evaluation only | E5: Prove that guardrail policy and evaluation can be separated from LiteLLM and reused across multiple gateways. | F5: None — this is the delivery entry point.
A6: M2 | B6: Internal multi-team platform | C6: Phase 2 | D6: Mode A — Remote Evaluation | E6: Allow multiple internal teams to onboard and operate distinct workloads. | F6: M1 complete: contract, policy format, Bedrock adapter, LiteLLM connector, observe mode, basic auditing and internal deployment all verified.
A7: M3 | B7: Guarded gateway | C7: Phase 3 | D7: Mode B — Guarded Gateway | E7: Offer a fully hosted model and guardrail path for teams without their own gateway. | F7: M2 complete — the full Phase 1–2 validation demonstration passed. Phase 3 lies beyond that gate and must not be resourced ahead of it.
A8: M4 | B8: Customer-managed runtime | C8: Phase 4 | D8: Mode C — Customer-Managed Runtime | E8: Support workloads that require local evaluation and content isolation. | F8: M2 complete, including the packaging validation. Does not require M3, though delivery sequencing treats Phase 4 as following Phase 3.
A9: M5 | B9: Advanced agent protection | C9: Phase 5 | D9: All modes — new evaluation stages, not a new deployment mode | E9: Extend guardrail coverage beyond prompt and response evaluation. | F9: M4 complete and validated. A separate product expansion — must not be scheduled or resourced as part of M1–M4 delivery.
A11: The full Phase 1–2 validation demonstration — all nine criteria together, against two genuinely independent deployments — passes at M2, not M1. No subset satisfies the gate.

Sheet Dependencies
A1: Dependencies
A2: What has to be true before the work can proceed, and who owns it. None is confirmed today.
A4: Dependency | B4: Type | C4: Needed for | D4: Owner | E4: Status | F4: Why it gates
A5: AWS account provisioning — non-production and production | B5: Internal | C5: Phase 1 kickoff — all infrastructure work | D5: Platform operations lead | E5: Unconfirmed | F5: Every other technical dependency is provisioned into one of these two accounts. It is the first link in the delivery chain, not one dependency among many.
A6: Amazon Bedrock Guardrails access in target Regions | B6: External | C6: Phase 1 — Bedrock Guardrails adapter | D6: Architecture lead | E6: Unconfirmed | F6: The first managed evaluation engine cannot be integrated or exercised without access in the Regions the runtime will serve.
A7: Stable evaluation contract before connector work | B7: Technical | C7: Phase 1 — LiteLLM connector | D7: Technical lead | E7: Not started | F7: Building the connector against a moving contract forces a matching connector revision on every change — and makes decision consistency across two independent instances unverifiable. Freeze and version the contract before connector work starts, not after.
A8: Consuming-team gateway availability and willingness to install the connector | B8: External | C8: Phase 1–2 — validation demonstration | D8: Integration lead / Delivery lead | E8: Unconfirmed | F8: The demonstration needs two organizationally independent instances. Both their existence and that team's cooperation are outside the delivery team's control.
A9: Security review sign-off | B9: Internal | C9: Any workload's observe-to-enforce promotion; any external onboarding | D9: Security and governance lead | E9: Not yet exercised | F9: No workload leaves observe without it, and the criteria that would satisfy it are themselves undefined today.
A10: KMS and Secrets Manager setup | B10: Technical | C10: Phase 1 — encryption at rest and in transit, runtime credential storage | D10: Platform operations lead / Technical lead | E10: Not started | F10: The runtime, policy storage and audit pipeline cannot be deployed with encryption and credential handling in place without them. Part of Phase 1 environment setup, not a later hardening pass.
A11: CI with dependency and container scanning | B11: Technical | C11: Every build from Phase 1 onward — release-blocking | D11: Technical lead | E11: Not started | F11: Required on every build and re-verified for each new deployment artifact, including the container, chart and template Phase 4 introduces. This one never resolves — it must stay continuously satisfied.
A13: Two sit outside the delivery team entirely: managed engine access in the target Regions, and a second team's willingness to run an independent instance. Neither waits on effort, so no AI-assistance factor touches them.

Sheet Release gates
A1: Release gates
A2: Pass or fail statements with a named owner. The nine validation gates must pass together — a subset does not satisfy the demonstration.
A4: ID | B4: Gate | C4: What passing means | D4: Accountable owner | E4: Milestone
A5: RG-MVP-01 | B5: Two instances, one policy | C5: Two independently deployed instances, each with its own connector installation, bound to the identical policy name and version and verified to resolve the same policy content. | D5: Delivery lead | E5: M1
A6: RG-MVP-02 | B6: No shared provider credentials | C6: Neither instance's model-provider credentials are held, stored or transmitted to the guardrail platform; verified against the platform's own stored secrets. | D6: Security and governance lead | E6: M1
A7: RG-MVP-03 | B7: Consistent normalized decisions | C7: Equivalent content submitted through both instances returns the identical normalized decision schema: action, allowed status, reason codes, policy name and version, evaluator metadata, correlation identifier. | D7: Delivery lead | E7: M1
A8: RG-MVP-04 | B8: Observe-mode workload | C8: One workload's binding is set to observe; evaluations execute and produce decisions with no enforcement applied on the request path. | D8: Delivery lead | E8: M1
A9: RG-MVP-05 | B9: Enforce-mode workload | C9: The other workload's binding is set to enforce or stricter; a violation triggers the corresponding action on the request path. | D9: Delivery lead | E9: M1
A10: RG-MVP-06 | B10: Policy upgrade and rollback | C10: A new immutable version is published and bound, producing a documented behavior change; the binding is then reverted with prior behavior restored, both transitions captured in audit metadata. | D10: Delivery lead | E10: M2
A11: RG-MVP-07 | B11: Raw-content persistence disablement | C11: With retention configured off, no raw content is found in any runtime store, cache or log after evaluation; decision metadata is still persisted. | D11: Security and governance lead | E11: M1
A12: RG-MVP-08 | B12: Configured failure policy honored | C12: With a detector or the Evaluation API forced into a defined failure condition, the configured behavior executes exactly as configured and the path taken is captured in audit. | D12: Delivery lead | E12: M1
A13: RG-MVP-09 | B13: Repackageable for customer-managed deployment | C13: The runtime packages as a deployable artifact suitable for a customer-managed environment while the connector's invocation contract stays unchanged. | D13: Delivery lead | E13: M1
A14: RG-NFR-01 | B14: Availability objective defined and monitored | C14: A documented availability objective for the hosted Evaluation API exists and has been published to pilot workload owners. The figure itself is TBD — this gate requires the objective to exist, not a number to be met. | D14: Platform operations lead | E14: M2
A15: RG-NFR-02 | B15: Evaluation latency measured and accepted | C15: End-to-end evaluation latency is measured continuously per stage and per deployment mode, and accepted by the pilot workload owners. | D15: Platform operations lead | E15: M2
... A20: RG-SEC-04 | B20: Container and dependency scan clean | C20: Every runtime image and declared dependency in the release is scanned for known vulnerabilities before release. | D20: Security and governance lead | E20: M1
A22: Verification method, environment and sign-off owner per criterion are only partly assigned upstream — a gap owed before the first phase exits.
